Workbook
Name Segment_L_REGION: #N/A

Sheet Tableau de bord
A1: Tableau de bord
R2: Evolution du tonnage de déchets | AG2: Evolution de la population dans chaque régions | BB2: Evolution des déchets par habitant
B8: Tonnage de déchets en 2021
B10: =GETPIVOTDATA("Somme de Tonnage de déchets en 2021",Traitement!$D$25) -> 41210634
B19: Tonnage de déchets en 2011
B21: =GETPIVOTDATA("Somme de Tonnage de déchets en 2011",Traitement!$D$25) -> 38445616
AG22: Population total en 2011 | AQ22: Population total en 2021 | BA22: Carte des evolution des déchets par habitants
AG24: =GETPIVOTDATA("Population en 2011",Traitement!$J$32) -> 64933400 | AQ24: =GETPIVOTDATA("Population en 2021",Traitement!$N$38) -> 67697091
F30: Régions ayant augmenté leur déchets par habitant
U31: Evolution de la population | AK31: Statut d'évolution des déchets
U33: =GETPIVOTDATA("Evolution de la population",Traitement!$D$53) -> 2763691 | AK33: =IF(COUNTA(Traitement!J56:J83)=28,"Sélectionner une région",Traitement!J57) -> Sélectionner une région
AK40: Statut d'évolution de la population
U41: Evolution des déchets par habitant
AJ42: =IF(COUNTA(Traitement!L60:L70)=11,"Sélectionner une région",Traitement!L60) -> Sélectionner une région
U43: =GETPIVOTDATA("Evolution",Traitement!$G$53) -> 0.22204345

Sheet Traitement
A3: Étiquettes de lignes | B3: Somme de Dechets par habitant en 2021 | C3: Somme de Dechets par habitant en 2011
A4: Auvergne-Rhône-Alpes | B4: 0.56399043 | C4: 0.55791283 | E4: Region | F4: X | G4: Y | H4: evolution | I4: Max Evolution | J4: Étiquettes de lignes | K4: Somme de Evolution
A5: Bourgogne-Franche-Comté | B5: 0.59650494 | C5: 0.5667059 | E5: Auvergne-Rhône-Alpes | F5: 8.6 | G5: 4.4 | H5: =VLOOKUP(J5,J$5:K$18,2,FALSE) -> 0.0060776061 | I5: =IF(H6=MAX(H$5:H$18),H6,"") | J5: Auvergne-Rhône-Alpes | K5: 0.0060776061
A6: Bretagne | B6: 0.72447102 | C6: 0.66198333 | E6: Bourgogne-Franche-Comté | F6: 9 | G6: 7 | H6: =VLOOKUP(J6,J$5:K$18,2,FALSE) -> 0.029799032 | I6: =IF(H7=MAX(H$5:H$18),H7,"") | J6: Bourgogne-Franche-Comté | K6: 0.029799032
A7: Centre-Val de Loire | B7: 0.62322001 | C7: 0.57435298 | E7: Bretagne | F7: 0.5 | G7: 7.8 | H7: =VLOOKUP(J7,J$5:K$18,2,FALSE) -> 0.062487692 | I7: =IF(H8=MAX(H$5:H$18),H8,"") | J7: Bretagne | K7: 0.062487692
A8: Corse | B8: 0.74509607 | C8: 0.68619109 | E8: Centre-Val de Loire | F8: 5.4 | G8: 7 | H8: =VLOOKUP(J8,J$5:K$18,2,FALSE) -> 0.048867034 | I8: =IF(H9=MAX(H$5:H$18),H9,"") | J8: Centre-Val de Loire | K8: 0.048867034
A9: DROM-COM | B9: 0.4344892 | C9: 0.64522808 | E9: Corse | F9: 13 | G9: 0 | H9: =VLOOKUP(J9,J$5:K$18,2,FALSE) -> 0.058904987 | I9: =IF(H10=MAX(H$5:H$18),H10,"") | J9: Corse | K9: 0.058904987
A10: Grand Est | B10: 0.55763395 | C10: 0.5559771 | E10: DROM-COM | F10: 13 | G10: 0 | H10: =VLOOKUP(J10,J$5:K$18,2,FALSE) -> -0.21073888 | I10: =IF(H11=MAX(H$5:H$18),H11,"") | J10: DROM-COM | K10: -0.21073888
A11: Hauts-de-France | B11: 0.71251883 | C11: 0.63707945 | E11: Grand Est | F11: 9.5 | G11: 8.7 | H11: =VLOOKUP(J11,J$5:K$18,2,FALSE) -> 0.0016568444 | I11: =IF(H12=MAX(H$5:H$18),H12,"") -> 0.075439381 | J11: Grand Est | K11: 0.0016568444
A12: Ile-de-France | B12: 0.4758684 | C12: 0.48255448 | E12: Hauts-de-France | F12: 6 | G12: 10.7 | H12: =VLOOKUP(J12,J$5:K$18,2,FALSE) -> 0.075439381 | I12: =IF(H13=MAX(H$5:H$18),H13,"") | J12: Hauts-de-France | K12: 0.075439381
A13: Normandie | B13: 0.72031974 | C13: 0.66637648 | E13: Ile-de-France | F13: 6 | G13: 9 | H13: =VLOOKUP(J13,J$5:K$18,2,FALSE) -> -0.0066860766 | I13: =IF(H14=MAX(H$5:H$18),H14,"") | J13: Ile-de-France | K13: -0.0066860766
A14: Nouvelle-Aquitaine | B14: 0.66805366 | C14: 0.63572125 | E14: Normandie | F14: 3.7 | G14: 9 | H14: =VLOOKUP(J14,J$5:K$18,2,FALSE) -> 0.053943263 | I14: =IF(H15=MAX(H$5:H$18),H15,"") | J14: Normandie | K14: 0.053943263
A15: Occitanie | B15: 0.64156982 | C15: 0.61523798 | E15: Nouvelle-Aquitaine | F15: 4 | G15: 4 | H15: =VLOOKUP(J15,J$5:K$18,2,FALSE) -> 0.032332406 | I15: =IF(H16=MAX(H$5:H$18),H16,"") | J15: Nouvelle-Aquitaine | K15: 0.032332406
A16: Pays de la Loire | B16: 0.6214966 | C16: 0.57891436 | E16: Occitanie | F16: 5.5 | G16: 2 | H16: =VLOOKUP(J16,J$5:K$18,2,FALSE) -> 0.02633184 | I16: =IF(H17=MAX(H$5:H$18),H17,"") | J16: Occitanie | K16: 0.02633184
A17: Provence-Alpes-Côte d'Azur | B17: 0.73022391 | C17: 0.72917784 | E17: Pays de la Loire | F17: 2.6 | G17: 6.8 | H17: =VLOOKUP(J17,J$5:K$18,2,FALSE) -> 0.042582246 | I17: =IF(H18=MAX(H$5:H$18),H18,"") | J17: Pays de la Loire | K17: 0.042582246
A18: Total général | B18: 8.8154566 | C18: 8.5934131 | E18: Provence-Alpes-Côte d'Azur | F18: 9.6 | G18: 2 | H18: =VLOOKUP(J18,J$5:K$18,2,FALSE) -> 0.0010460739 | J18: Provence-Alpes-Côte d'Azur | K18: 0.0010460739
J19: Total général | K19: 0.22204345
A22: Étiquettes de lignes | B22: Somme de Evolution de la population | I22: =IF(H6=MIN(H$5:H$18),H6,"")
A23: Auvergne-Rhône-Alpes | B23: 480138 | I23: =IF(H7=MIN(H$5:H$18),H7,"")
A24: Bretagne | B24: 176800 | I24: =IF(H8=MIN(H$5:H$18),H8,"")
A25: Centre-Val de Loire | B25: 16468 | D25: Étiquettes de lignes | E25: Somme de Tonnage de déchets en 2021 | F25: Somme de Tonnage de déchets en 2011 | I25: =IF(H9=MIN(H$5:H$18),H9,"")
A26: Corse | B26: 33111 | D26: Auvergne-Rhône-Alpes | E26: 4576422 | F26: 4259231
A27: DROM-COM | B27: 328822 | D27: Bourgogne-Franche-Comté | E27: 1670329.5 | F27: 1595942.4 | I27: =IF(H11=MIN(H$5:H$18),H11,"")
A28: Grand Est | B28: 22252 | D28: Bretagne | E28: 2459265.4 | F28: 2130108.1 | I28: =IF(H12=MIN(H$5:H$18),H12,"")
A29: Hauts-de-France | B29: 35122 | D29: Centre-Val de Loire | E29: 1603733.9 | F29: 1468525.8 | I29: =IF(H13=MIN(H$5:H$18),H13,"")
A30: Ile-de-France | B30: 464428 | D30: Corse | E30: 258993.16 | F30: 215797.49 | I30: =IF(H14=MIN(H$5:H$18),H14,"")
A31: Normandie | B31: 12889 | D31: DROM-COM | E31: 952347.31 | F31: 1202096 | I31: =IF(H15=MIN(H$5:H$18),H15,"")
A32: Nouvelle-Aquitaine | B32: 296274 | D32: Grand Est | E32: 3101162.4 | F32: 3079576.6 | I32: =IF(H16=MIN(H$5:H$18),H16,"") | J32: Étiquettes de lignes | K32: Somme de Population en 2011
A33: Occitanie | B33: 448710 | D33: Hauts-de-France | E33: 4271758.5 | F33: 3797101.9 | I33: =IF(H17=MIN(H$5:H$18),H17,"") | J33: Auvergne-Rhône-Alpes | K33: 7634223
A34: Pays de la Loire | B34: 252886 | D34: Ile-de-France | E34: 5861403.9 | F34: 5719646.3 | I34: =IF(H18=MIN(H$5:H$18),H18,"") | J34: Bourgogne-Franche-Comté | K34: 2816174
A35: Provence-Alpes-Côte d'Azur | B35: 211771 | D35: Normandie | E35: 2397199.6 | F35: 2209089.3 | I35: =IF(H19=MIN(H$5:H$18),H19,"") | J35: Bretagne | K35: 3217767
A36: Total général | B36: 2779671 | D36: Nouvelle-Aquitaine | E36: 4054652.8 | F36: 3670068.4 | I36: =IF(H20=MIN(H$5:H$18),H20,"") | J36: Centre-Val de Loire | K36: 2556835
D37: Occitanie | E37: 3863646.4 | F37: 3429008 | I37: =IF(H21=MIN(H$5:H$18),H21,"") | J37: Corse | K37: 314486
D38: Pays de la Loire | E38: 2395247.3 | F38: 2084736 | I38: =IF(H22=MIN(H$5:H$18),H22,"") | J38: DROM-COM | K38: 1863056 | N38: Étiquettes de lignes | O38: Somme de Population en 2021
D39: Provence-Alpes-Côte d'Azur | E39: 3744471.4 | F39: 3584688.6 | I39: =IF(H23=MIN(H$5:H$18),H23,"") | J39: Grand Est | K39: 5539035 | N39: Auvergne-Rhône-Alpes | O39: 8114361
D40: Total général | E40: 41210634 | F40: 38445616 | I40: =IF(H24=MIN(H$5:H$18),H24,"") | J40: Hauts-de-France | K40: 5960170 | N40: Bourgogne-Franche-Comté | O40: 2800194
I41: =IF(H25=MIN(H$5:H$18),H25,"") | J41: Ile-de-France | K41: 11852851 | N41: Bretagne | O41: 3394567
I42: =IF(H26=MIN(H$5:H$18),H26,"") | J42: Normandie | K42: 3315077 | N42: Centre-Val de Loire | O42: 2573303
I43: =IF(H27=MIN(H$5:H$18),H27,"") | J43: Nouvelle-Aquitaine | K43: 5773078 | N43: Corse | O43: 347597
I44: =IF(H28=MIN(H$5:H$18),H28,"") | J44: Occitanie | K44: 5573466 | N44: DROM-COM | O44: 2191878
...

Sheet Statut de volume de dechet
A1: L_REGION | B1: Tonnage de déchets en 2011 | C1: Population en 2011 | D1: Dechets par habitant en 2011 | E1: Tonnage de déchets en 2021 | F1: Population en 2021 | G1: Dechets par habitant en 2021 | H1: Evolution | I1: Statut | J1: Evolution de la population | K1: Statut d'évolution de la population
A2: Auvergne-Rhône-Alpes | B2: 4259231 | C2: 7634223 | D2: 0.55791283 | E2: 4576422 | F2: 8114361 | G2: 0.56399043 | H2: 0.0060776061 | I2: Stable | J2: 480138 | K2: Forte augmentation de la population
A3: Bourgogne-Franche-Comté | B3: 1595942.4 | C3: 2816174 | D3: 0.5667059 | E3: 1670329.5 | F3: 2800194 | G3: 0.59650494 | H3: 0.029799032 | I3: Augmentation faible | J3: -15980 | K3: Baisse de la population
A4: Bretagne | B4: 2130108.1 | C4: 3217767 | D4: 0.66198333 | E4: 2459265.4 | F4: 3394567 | G4: 0.72447102 | H4: 0.062487692 | I4: Forte augmentation | J4: 176800 | K4: Légére augmentation de la population
A5: Centre-Val de Loire | B5: 1468525.8 | C5: 2556835 | D5: 0.57435298 | E5: 1603733.9 | F5: 2573303 | G5: 0.62322001 | H5: 0.048867034 | I5: Augmentation faible | J5: 16468 | K5: Trés légére augmentation de la population
A6: Corse | B6: 215797.49 | C6: 314486 | D6: 0.68619109 | E6: 258993.16 | F6: 347597 | G6: 0.74509607 | H6: 0.058904987 | I6: Forte augmentation | J6: 33111 | K6: Trés légére augmentation de la population
A7: Grand Est | B7: 3079576.6 | C7: 5539035 | D7: 0.5559771 | E7: 3101162.4 | F7: 5561287 | G7: 0.55763395 | H7: 0.0016568444 | I7: Stable | J7: 22252 | K7: Trés légére augmentation de la population
A8: Hauts-de-France | B8: 3797101.9 | C8: 5960170 | D8: 0.63707945 | E8: 4271758.5 | F8: 5995292 | G8: 0.71251883 | H8: 0.075439381 | I8: Forte augmentation | J8: 35122 | K8: Trés légére augmentation de la population
A9: Ile-de-France | B9: 5719646.3 | C9: 11852851 | D9: 0.48255448 | E9: 5861403.9 | F9: 12317279 | G9: 0.4758684 | H9: -0.0066860766 | I9: Stable | J9: 464428 | K9: Forte augmentation de la population
A10: Normandie | B10: 2209089.3 | C10: 3315077 | D10: 0.66637648 | E10: 2397199.6 | F10: 3327966 | G10: 0.72031974 | H10: 0.053943263 | I10: Forte augmentation | J10: 12889 | K10: Trés légére augmentation de la population
A11: Nouvelle-Aquitaine | B11: 3670068.4 | C11: 5773078 | D11: 0.63572125 | E11: 4054652.8 | F11: 6069352 | G11: 0.66805366 | H11: 0.032332406 | I11: Augmentation faible | J11: 296274 | K11: Forte augmentation de la population
A12: Occitanie | B12: 3429008 | C12: 5573466 | D12: 0.61523798 | E12: 3863646.4 | F12: 6022176 | G12: 0.64156982 | H12: 0.02633184 | I12: Augmentation faible | J12: 448710 | K12: Forte augmentation de la population
A13: Pays de la Loire | B13: 2084736 | C13: 3601113 | D13: 0.57891436 | E13: 2395247.3 | F13: 3853999 | G13: 0.6214966 | H13: 0.042582246 | I13: Augmentation faible | J13: 252886 | K13: Forte augmentation de la population
... A15: DROM-COM | B15: 1202096 | C15: 1863056 | D15: 0.64522808 | E15: 952347.31 | F15: 2191878 | G15: 0.4344892 | H15: -0.21073888 | I15: Trés forte amélioration | J15: 328822 | K15: Forte augmentation de la population
B18: Comment la production de déchets par habitant a-t-elle évolué entre 2011 et 2021 par région
